<?xml version="1.0" ?>
<!-- =================================================================================== -->
<!-- |    This document was autogenerated by xacro from linorobot.xacro                | -->
<!-- |    EDITING THIS FILE BY HAND IS NOT RECOMMENDED                                 | -->
<!-- =================================================================================== -->
<!-- XML namespaces -->
<robot name="gizmo">
  <!-- ============================  A Few Color Macros  ============================ -->
  <!-- ============================  A Few Color Macros  ============================ -->
  <link name="base_footprint">
    <visual>
      <origin rpy="0 0 0" xyz="0 0 0"/>
      <geometry>
        <box size="0.1 0.1 0.005"/>
      </geometry>
      <material name="gold">
        <color rgba="0.5 0.3 0 1.0"/>
      </material>
    </visual>
    <collision>
      <origin rpy="0 0 0" xyz="0 0 0"/>
      <geometry>
        <box size="0.1 0.1 0.005"/>
      </geometry>
      <inertial>
        <mass value="0.01"/>
        <inertia ixx="0.0001" ixy="0.0" ixz="0.0" iyy="0.0001" iyz="0.0" izz="0.0001"/>
      </inertial>
    </collision>
  </link>
  <gazebo reference="base_footprint">
    <material>Gazebo/FlatBlack</material>
    <selfCollide>false</selfCollide>
    <turnGravityOff>false</turnGravityOff>
  </gazebo>
  <link name="imu_base">
    <visual>
      <origin rpy="0 0 0" xyz="0 0 0"/>
      <geometry>
        <box size="0.01 0.01 0.005"/>
      </geometry>
      <material name="black">
        <color rgba="0.1 0.1 0.1 1.0"/>
      </material>
    </visual>
    <collision>
      <origin rpy="0 0 0" xyz="0 0 0"/>
      <geometry>
        <box size="0.01 0.01 0.005"/>
      </geometry>
      <inertial>
        <mass value="0.01"/>
        <inertia ixx="0.0001" ixy="0.0" ixz="0.0" iyy="0.0001" iyz="0.0" izz="0.0001"/>
      </inertial>
    </collision>
  </link>
  <gazebo reference="imu_base">
    <material>Gazebo/FlatBlack</material>
    <selfCollide>false</selfCollide>
    <turnGravityOff>false</turnGravityOff>
  </gazebo>
  <link name="base_link">
    <visual>
      <geometry>
        <mesh filename="package://robbie/mesh/base.stl" scale="0.001 0.001 0.001"/>
      </geometry>
      <material name="White">
        <color rgba="1.0 1.0 1.0 1.0"/>
      </material>
      <origin rpy="0 0 0" xyz="0 0 0"/>
    </visual>
    <collision>
      <origin rpy="0 0 0" xyz="0 0 0"/>
      <geometry>
        <mesh filename="package://robbie/mesh/base.stl" scale="0.001 0.001 0.001"/>
      </geometry>
    </collision>
  </link>
  <link name="kinect_link">
    <inertial>
      <mass value="1.0"/>
      <origin xyz="0 0 0"/>
      <inertia ixx="1.0" ixy="0.0" ixz="0.0" iyy="1.0" iyz="0.0" izz="1.0"/>
    </inertial>
    <visual>
      <origin rpy="0 0 0" xyz=" 0 0 0 "/>
      <geometry>
        <mesh filename="package://robbie/mesh/kinect.stl" scale="0.001 0.001 0.001"/>
      </geometry>
      <material name="ax12_color">
        <color rgba="0.1 0.1 0.1 1.0"/>
      </material>
    </visual>
    <collision>
      <origin rpy="0 0 0" xyz="0 0 0"/>
      <geometry>
        <mesh filename="package://robbie/mesh/kinect.stl" scale="0.001 0.001 0.001"/>
      </geometry>
    </collision>
  </link>
  <link name="elbow_joint_r">
    <visual>
      <origin rpy="0 0 0" xyz="0 0 0"/>
      <geometry>
        <box size="0.042 0.042 0.042"/>
      </geometry>
      <material name="yellow2">
        <color rgba="0.8 0.9 0 1.0"/>
      </material>
    </visual>
    <collision>
      <origin rpy="0 0 0" xyz="0 0 0"/>
      <geometry>
        <box size="0.042 0.042 0.042"/>
      </geometry>
      <inertial>
        <mass value="0.01"/>
        <inertia ixx="0.0001" ixy="0.0" ixz="0.0" iyy="0.0001" iyz="0.0" izz="0.0001"/>
      </inertial>
    </collision>
  </link>
  <gazebo reference="elbow_joint_r">
    <material>Gazebo/FlatBlack</material>
    <selfCollide>false</selfCollide>
    <turnGravityOff>false</turnGravityOff>
  </gazebo>
  <link name="elbow_joint_l">
    <visual>
      <origin rpy="0 0 0" xyz="0 0 0"/>
      <geometry>
        <box size="0.042 0.042 0.042"/>
      </geometry>
      <material name="yellow2">
        <color rgba="0.8 0.9 0 1.0"/>
      </material>
    </visual>
    <collision>
      <origin rpy="0 0 0" xyz="0 0 0"/>
      <geometry>
        <box size="0.042 0.042 0.042"/>
      </geometry>
      <inertial>
        <mass value="0.01"/>
        <inertia ixx="0.0001" ixy="0.0" ixz="0.0" iyy="0.0001" iyz="0.0" izz="0.0001"/>
      </inertial>
    </collision>
  </link>
  <gazebo reference="elbow_joint_l">
    <material>Gazebo/FlatBlack</material>
    <selfCollide>false</selfCollide>
    <turnGravityOff>false</turnGravityOff>
  </gazebo>
  <link name="torso_link">
    <visual>
      <geometry>
        <mesh filename="package://robbie/mesh/gizmo2_torso.stl" scale="0.001 0.001 0.001"/>
      </geometry>
      <material name="grey1">
        <color rgba="0.75 0.75 0.75 1.0"/>
      </material>
      <origin rpy="0 0 0" xyz="0 0 0"/>
    </visual>
    <collision>
      <origin rpy="0 0 0" xyz="-0 0 0"/>
      <geometry>
        <mesh filename="package://robbie/mesh/gizmo2_torso.stl" scale="0.001 0.001 0.001"/>
      </geometry>
    </collision>
  </link>
  <link name="scanner_link">
    <visual>
      <geometry>
        <mesh filename="package://robbie/mesh/X4.stl" scale="0.001 0.001 0.001"/>
      </geometry>
      <material name="grey1">
        <color rgba="0.75 0.75 0.75 1.0"/>
      </material>
      <origin rpy="0 0 0" xyz="0 0 0"/>
    </visual>
    <collision>
      <origin rpy="0 0 0" xyz="-0 0 0"/>
      <geometry>
        <mesh filename="package://robbie/mesh/X4.stl" scale="0.001 0.001 0.001"/>
      </geometry>
    </collision>
  </link>
  <link name="pan_link">
    <visual>
      <origin rpy=" 1.57 0 1.57" xyz="0 0 0"/>
      <geometry>
        <mesh filename="package://r2_description/mesh/ax12.stl" scale="0.001 0.001 0.001"/>
      </geometry>
      <material name="ax12_color">
        <color rgba="0.1 0.1 0.1 1.0"/>
      </material>
    </visual>
    <collision>
      <origin rpy=" 1.57 0 1.57" xyz="0 0 0"/>
      <geometry>
        <!--<box size="0.032 0.038 0.05" />-->
        <mesh filename="package://r2_description/mesh/ax12.stl" scale="0.001 0.001 0.001"/>
      </geometry>
    </collision>
    <inertial>
      <mass value="0.055"/>
      <inertia ixx="0.0001" ixy="0.0" ixz="0.0" iyy="0.0001" iyz="0.0" izz="0.0001"/>
    </inertial>
  </link>
  <gazebo reference="pan_link">
    <material>Gazebo/FlatBlack</material>
    <selfCollide>false</selfCollide>
    <turnGravityOff>false</turnGravityOff>
  </gazebo>
  <link name="head_pan_link">
    <visual>
      <origin rpy="0 0 0" xyz="0 0 0"/>
      <geometry>
        <box size="0.15 0.1 0.005"/>
      </geometry>
      <material name="blue">
        <color rgba="0 0 0.9 1.0"/>
      </material>
    </visual>
    <collision>
      <origin rpy="0 0 0" xyz="0 0 0"/>
      <geometry>
        <box size="0.15 0.1 0.005"/>
      </geometry>
      <inertial>
        <mass value="0.01"/>
        <inertia ixx="0.0001" ixy="0.0" ixz="0.0" iyy="0.0001" iyz="0.0" izz="0.0001"/>
      </inertial>
    </collision>
  </link>
  <gazebo reference="head_pan_link">
    <material>Gazebo/FlatBlack</material>
    <selfCollide>false</selfCollide>
    <turnGravityOff>false</turnGravityOff>
  </gazebo>
  <link name="head_tilt_link">
    <visual>
      <origin rpy="0 0 3.14" xyz="0 0 0"/>
      <geometry>
        <mesh filename="package://r2_description/mesh/ax12.stl" scale="0.001 0.001 0.001"/>
      </geometry>
      <material name="ax12_color">
        <color rgba="0.1 0.1 0.1 1.0"/>
      </material>
    </visual>
    <collision>
      <origin rpy="0 0 3.14" xyz="0 0 0"/>
      <geometry>
        <!--<box size="0.032 0.038 0.05" />-->
        <mesh filename="package://r2_description/mesh/ax12.stl" scale="0.001 0.001 0.001"/>
      </geometry>
    </collision>
    <inertial>
      <mass value="0.055"/>
      <inertia ixx="0.0001" ixy="0.0" ixz="0.0" iyy="0.0001" iyz="0.0" izz="0.0001"/>
    </inertial>
  </link>
  <gazebo reference="head_tilt_link">
    <material>Gazebo/FlatBlack</material>
    <selfCollide>false</selfCollide>
    <turnGravityOff>false</turnGravityOff>
  </gazebo>
  <link name="head_tilt_r_bracket_f2">
    <visual>
      <origin rpy="0 0 0" xyz="0 0 0"/>
      <geometry>
        <mesh filename="package://r2_description/mesh/F2.stl" scale="0.001 0.001 0.001"/>
      </geometry>
      <material name="bracket_color">
        <color rgba="0.9 0.9 0.9 1.0"/>
      </material>
    </visual>
    <collision>
      <origin rpy="0 0 0" xyz="0 0 0"/>
      <geometry>
        <mesh filename="package://r2_description/mesh/F2.stl" scale="0.001 0.001 0.001"/>
      </geometry>
    </collision>
    <inertial>
      <mass value="0.02"/>
      <inertia ixx="0.0001" ixy="0.0" ixz="0.0" iyy="0.0001" iyz="0.0" izz="0.0001"/>
    </inertial>
  </link>
  <gazebo reference="head_tilt_r_bracket_f2">
    <material>Gazebo/White</material>
    <selfCollide>false</selfCollide>
    <turnGravityOff>false</turnGravityOff>
  </gazebo>
  <link name="neck">
    <visual>
      <geometry>
        <mesh filename="package://robbie/mesh/gizmo_neck1.stl" scale="0.001 0.001 0.001"/>
      </geometry>
      <material name="grey1">
        <color rgba="0.75 0.75 0.75 1.0"/>
      </material>
      <origin rpy="0 0 0" xyz="0 0 0"/>
    </visual>
    <collision>
      <origin rpy="0 0 0" xyz="-0 0 0"/>
      <geometry>
        <mesh filename="package://robbie/mesh/gizmo_neck1.stl" scale="0.001 0.001 0.001"/>
      </geometry>
    </collision>
  </link>
  <link name="head">
    <visual>
      <geometry>
        <mesh filename="package://robbie/mesh/head1.stl" scale="0.0034 0.0034 0.0034"/>
      </geometry>
      <material name="grey1">
        <color rgba="0.75 0.75 0.75 1.0"/>
      </material>
      <origin rpy="0 0 0" xyz="0 0 0"/>
    </visual>
    <collision>
      <origin rpy="0 0 0" xyz="-0 0 0"/>
      <geometry>
        <mesh filename="package://robbie/mesh/head1.stl" scale="0.0034 0.0034 0.0034"/>
      </geometry>
    </collision>
  </link>
  <link name="camera_link">
    <visual>
      <origin rpy="0 1.57 0" xyz="0 0 0"/>
      <geometry>
        <cylinder length="0.025" radius="0.01"/>
      </geometry>
      <material name="grey1">
        <color rgba="0.75 0.75 0.75 1.0"/>
      </material>
    </visual>
    <collision>
      <origin rpy="0 1.57 0" xyz="0 0 0"/>
      <geometry>
        <cylinder length="0.025" radius="0.01"/>
      </geometry>
    </collision>
    <inertial>
      <mass value="0.1"/>
      <inertia ixx="0.0001" ixy="0.0" ixz="0.0" iyy="0.0001" iyz="0.0" izz="0.0001"/>
    </inertial>
  </link>
  <gazebo reference="camera_link">
    <material>Gazebo/Grey</material>
    <selfCollide>false</selfCollide>
    <turnGravityOff>false</turnGravityOff>
  </gazebo>
  <link name="right_rotate">
    <visual>
      <geometry>
        <mesh filename="package://robbie/mesh/gizmo2_servo_r.stl" scale="0.001 0.001 0.001"/>
      </geometry>
      <material name="black">
        <color rgba="0.1 0.1 0.1 1.0"/>
      </material>
      <origin rpy="0 0 0" xyz="0 0 0"/>
    </visual>
    <collision>
      <origin rpy="0 0 0" xyz="-0 0 0"/>
      <geometry>
        <mesh filename="package://robbie/mesh/gizmo2_servo_r.stl" scale="0.001 0.001 0.001"/>
      </geometry>
    </collision>
  </link>
  <link name="left_rotate">
    <visual>
      <geometry>
        <mesh filename="package://robbie/mesh/gizmo2_servo_l.stl" scale="0.001 0.001 0.001"/>
      </geometry>
      <material name="black">
        <color rgba="0.1 0.1 0.1 1.0"/>
      </material>
      <origin rpy="0 0 0" xyz="0 0 0"/>
    </visual>
    <collision>
      <origin rpy="0 0 0" xyz="-0 0 0"/>
      <geometry>
        <mesh filename="package://robbie/mesh/gizmo2_servo_l.stl" scale="0.001 0.001 0.001"/>
      </geometry>
    </collision>
  </link>
  <link name="right_lift_link">
    <visual>
      <geometry>
        <mesh filename="package://robbie/mesh/gizmo_upper_arm_r2.stl" scale="0.001 0.001 0.001"/>
      </geometry>
      <material name="grey1">
        <color rgba="0.75 0.75 0.75 1.0"/>
      </material>
      <origin rpy="0 0 0" xyz="0 0 0"/>
    </visual>
    <collision>
      <origin rpy="0 0 0" xyz="-0 0 0"/>
      <geometry>
        <mesh filename="package://robbie/mesh/gizmo_upper_arm_r2.stl" scale="0.001 0.001 0.001"/>
      </geometry>
    </collision>
  </link>
  <link name="left_lift_link">
    <visual>
      <geometry>
        <mesh filename="package://robbie/mesh/gizmo_upper_arm_l2.stl" scale="0.001 0.001 0.001"/>
      </geometry>
      <material name="grey1">
        <color rgba="0.75 0.75 0.75 1.0"/>
      </material>
      <origin rpy="0 0 0" xyz="0 0 0"/>
    </visual>
    <collision>
      <origin rpy="0 0 0" xyz="-0 0 0"/>
      <geometry>
        <mesh filename="package://robbie/mesh/gizmo_upper_arm_l2.stl" scale="0.001 0.001 0.001"/>
      </geometry>
    </collision>
  </link>
  <link name="servo_r4">
    <visual>
      <geometry>
        <mesh filename="package://robbie/mesh/servo.stl" scale="0.001 0.001 0.001"/>
      </geometry>
      <material name="White">
        <color rgba="1.0 1.0 1.0 1.0"/>
      </material>
      <origin rpy="0 0 0" xyz="0 0 0"/>
    </visual>
    <collision>
      <origin rpy="0 0 0" xyz="0 0 0"/>
      <geometry>
        <mesh filename="package://robbie/mesh/servo.stl" scale="0.001 0.001 0.001"/>
      </geometry>
    </collision>
  </link>
  <link name="r_bracket5">
    <visual>
      <geometry>
        <mesh filename="package://robbie/mesh/drive_bracket1.stl" scale="0.001 0.001 0.001"/>
      </geometry>
      <material name="White">
        <color rgba="1.0 1.0 1.0 1.0"/>
      </material>
      <origin rpy="0 0 0" xyz="0 0 0"/>
    </visual>
    <collision>
      <origin rpy="0 0 0" xyz="0 0 0"/>
      <geometry>
        <mesh filename="package://robbie/mesh/drive_bracket1.stl" scale="0.001 0.001 0.001"/>
      </geometry>
    </collision>
  </link>
  <link name="servo_r5">
    <visual>
      <geometry>
        <mesh filename="package://robbie/mesh/servo.stl" scale="0.001 0.001 0.001"/>
      </geometry>
      <material name="White">
        <color rgba="1.0 1.0 1.0 1.0"/>
      </material>
      <origin rpy="0 0 0" xyz="0 0 0"/>
    </visual>
    <collision>
      <origin rpy="0 0 0" xyz="0 0 0"/>
      <geometry>
        <mesh filename="package://robbie/mesh/servo.stl" scale="0.001 0.001 0.001"/>
      </geometry>
    </collision>
  </link>
  <link name="r_bracket6">
    <visual>
      <geometry>
        <mesh filename="package://robbie/mesh/drive_bracket1.stl" scale="0.001 0.001 0.001"/>
      </geometry>
      <material name="White">
        <color rgba="1.0 1.0 1.0 1.0"/>
      </material>
      <origin rpy="0 0 0" xyz="0 0 0"/>
    </visual>
    <collision>
      <origin rpy="0 0 0" xyz="0 0 0"/>
      <geometry>
        <mesh filename="package://robbie/mesh/drive_bracket1.stl" scale="0.001 0.001 0.001"/>
      </geometry>
    </collision>
  </link>
  <link name="servo_r6">
    <visual>
      <geometry>
        <mesh filename="package://robbie/mesh/servo.stl" scale="0.001 0.001 0.001"/>
      </geometry>
      <material name="White">
        <color rgba="1.0 1.0 1.0 1.0"/>
      </material>
      <origin rpy="0 0 0" xyz="0 0 0"/>
    </visual>
    <collision>
      <origin rpy="0 0 0" xyz="0 0 0"/>
      <geometry>
        <mesh filename="package://robbie/mesh/servo.stl" scale="0.001 0.001 0.001"/>
      </geometry>
    </collision>
  </link>
  <link name="r_bracket7">
    <visual>
      <geometry>
        <mesh filename="package://robbie/mesh/drive_bracket1.stl" scale="0.001 0.001 0.001"/>
      </geometry>
      <material name="White">
        <color rgba="1.0 1.0 1.0 1.0"/>
      </material>
      <origin rpy="0 0 0" xyz="0 0 0"/>
    </visual>
    <collision>
      <origin rpy="0 0 0" xyz="0 0 0"/>
      <geometry>
        <mesh filename="package://robbie/mesh/drive_bracket1.stl" scale="0.001 0.001 0.001"/>
      </geometry>
    </collision>
  </link>
  <link name="servo_r7">
    <visual>
      <geometry>
        <mesh filename="package://robbie/mesh/servo.stl" scale="0.001 0.001 0.001"/>
      </geometry>
      <material name="White">
        <color rgba="1.0 1.0 1.0 1.0"/>
      </material>
      <origin rpy="0 0 0" xyz="0 0 0"/>
    </visual>
    <collision>
      <origin rpy="0 0 0" xyz="0 0 0"/>
      <geometry>
        <mesh filename="package://robbie/mesh/servo.stl" scale="0.001 0.001 0.001"/>
      </geometry>
    </collision>
  </link>
  <link name="r_bracket8">
    <visual>
      <geometry>
        <mesh filename="package://robbie/mesh/drive_bracket1.stl" scale="0.001 0.001 0.001"/>
      </geometry>
      <material name="White">
        <color rgba="1.0 1.0 1.0 1.0"/>
      </material>
      <origin rpy="0 0 0" xyz="0 0 0"/>
    </visual>
    <collision>
      <origin rpy="0 0 0" xyz="0 0 0"/>
      <geometry>
        <mesh filename="package://robbie/mesh/drive_bracket1.stl" scale="0.001 0.001 0.001"/>
      </geometry>
    </collision>
  </link>
  <link name="servo_l4">
    <visual>
      <geometry>
        <mesh filename="package://robbie/mesh/servo.stl" scale="0.001 0.001 0.001"/>
      </geometry>
      <material name="White">
        <color rgba="1.0 1.0 1.0 1.0"/>
      </material>
      <origin rpy="0 0 0" xyz="0 0 0"/>
    </visual>
    <collision>
      <origin rpy="0 0 0" xyz="0 0 0"/>
      <geometry>
        <mesh filename="package://robbie/mesh/servo.stl" scale="0.001 0.001 0.001"/>
      </geometry>
    </collision>
  </link>
  <link name="l_bracket5">
    <visual>
      <geometry>
        <mesh filename="package://robbie/mesh/drive_bracket1.stl" scale="0.001 0.001 0.001"/>
      </geometry>
      <material name="White">
        <color rgba="1.0 1.0 1.0 1.0"/>
      </material>
      <origin rpy="0 0 0" xyz="0 0 0"/>
    </visual>
    <collision>
      <origin rpy="0 0 0" xyz="0 0 0"/>
      <geometry>
        <mesh filename="package://robbie/mesh/drive_bracket1.stl" scale="0.001 0.001 0.001"/>
      </geometry>
    </collision>
  </link>
  <link name="servo_l5">
    <visual>
      <geometry>
        <mesh filename="package://robbie/mesh/servo.stl" scale="0.001 0.001 0.001"/>
      </geometry>
      <material name="White">
        <color rgba="1.0 1.0 1.0 1.0"/>
      </material>
      <origin rpy="0 0 0" xyz="0 0 0"/>
    </visual>
    <collision>
      <origin rpy="0 0 0" xyz="0 0 0"/>
      <geometry>
        <mesh filename="package://robbie/mesh/servo.stl" scale="0.001 0.001 0.001"/>
      </geometry>
    </collision>
  </link>
  <link name="l_bracket6">
    <visual>
      <geometry>
        <mesh filename="package://robbie/mesh/drive_bracket1.stl" scale="0.001 0.001 0.001"/>
      </geometry>
      <material name="White">
        <color rgba="1.0 1.0 1.0 1.0"/>
      </material>
      <origin rpy="0 0 0" xyz="0 0 0"/>
    </visual>
    <collision>
      <origin rpy="0 0 0" xyz="0 0 0"/>
      <geometry>
        <mesh filename="package://robbie/mesh/drive_bracket1.stl" scale="0.001 0.001 0.001"/>
      </geometry>
    </collision>
  </link>
  <link name="servo_l6">
    <visual>
      <geometry>
        <mesh filename="package://robbie/mesh/servo.stl" scale="0.001 0.001 0.001"/>
      </geometry>
      <material name="White">
        <color rgba="1.0 1.0 1.0 1.0"/>
      </material>
      <origin rpy="0 0 0" xyz="0 0 0"/>
    </visual>
    <collision>
      <origin rpy="0 0 0" xyz="0 0 0"/>
      <geometry>
        <mesh filename="package://robbie/mesh/servo.stl" scale="0.001 0.001 0.001"/>
      </geometry>
    </collision>
  </link>
  <link name="l_bracket7">
    <visual>
      <geometry>
        <mesh filename="package://robbie/mesh/drive_bracket1.stl" scale="0.001 0.001 0.001"/>
      </geometry>
      <material name="White">
        <color rgba="1.0 1.0 1.0 1.0"/>
      </material>
      <origin rpy="0 0 0" xyz="0 0 0"/>
    </visual>
    <collision>
      <origin rpy="0 0 0" xyz="0 0 0"/>
      <geometry>
        <mesh filename="package://robbie/mesh/drive_bracket1.stl" scale="0.001 0.001 0.001"/>
      </geometry>
    </collision>
  </link>
  <link name="servo_l7">
    <visual>
      <geometry>
        <mesh filename="package://robbie/mesh/servo.stl" scale="0.001 0.001 0.001"/>
      </geometry>
      <material name="White">
        <color rgba="1.0 1.0 1.0 1.0"/>
      </material>
      <origin rpy="0 0 0" xyz="0 0 0"/>
    </visual>
    <collision>
      <origin rpy="0 0 0" xyz="0 0 0"/>
      <geometry>
        <mesh filename="package://robbie/mesh/servo.stl" scale="0.001 0.001 0.001"/>
      </geometry>
    </collision>
  </link>
  <link name="l_bracket8">
    <visual>
      <geometry>
        <mesh filename="package://robbie/mesh/drive_bracket1.stl" scale="0.001 0.001 0.001"/>
      </geometry>
      <material name="White">
        <color rgba="1.0 1.0 1.0 1.0"/>
      </material>
      <origin rpy="0 0 0" xyz="0 0 0"/>
    </visual>
    <collision>
      <origin rpy="0 0 0" xyz="0 0 0"/>
      <geometry>
        <mesh filename="package://robbie/mesh/drive_bracket1.stl" scale="0.001 0.001 0.001"/>
      </geometry>
    </collision>
  </link>
  <!--############################# right arm ################-->
  <joint name="joint8" type="revolute">
    <parent link="torso_link"/>
    <child link="right_rotate"/>
    <origin rpy="0 0 0" xyz="0.01 -0.13 0.65"/>
    <axis xyz="0 0 1"/>
    <limit effort="100" lower="-0.89" upper="1.41" velocity="0.5"/>
    <dynamics damping="0.0"/>
  </joint>
  <joint name="joint9" type="revolute">
    <parent link="right_rotate"/>
    <child link="right_lift_link"/>
    <origin rpy="0 0 0" xyz="0 -0.03 -0"/>
    <axis xyz="0 1 0"/>
    <limit effort="100" lower="-2" upper="2" velocity="0.5"/>
    <dynamics damping="0.0"/>
  </joint>
  <joint name="joint10" type="revolute">
    <parent link="right_lift_link"/>
    <child link="elbow_joint_r"/>
    <origin rpy="0 0 0" xyz="0.15 -0.03 -0"/>
    <axis xyz="1 0 0"/>
    <limit effort="100" lower="-1.57" upper="1.57" velocity="0.5"/>
    <dynamics damping="0.0"/>
  </joint>
  <joint name="servo_r4_link" type="fixed">
    <parent link="elbow_joint_r"/>
    <child link="servo_r4"/>
    <origin rpy="1.57 0 1.57" xyz="0.02 -0.02 -0.01"/>
    <dynamics damping="0.0"/>
  </joint>
  <joint name="joint11" type="revolute">
    <parent link="servo_r4"/>
    <child link="r_bracket5"/>
    <origin rpy="0 3.14 1.57" xyz="0.02 0.01 0.04"/>
    <axis xyz="0 1 0"/>
    <limit effort="100" lower="-1.57" upper="1.57" velocity="0.5"/>
    <dynamics damping="0.0"/>
  </joint>
  <joint name="servo_r5_link" type="fixed">
    <parent link="r_bracket5"/>
    <child link="servo_r5"/>
    <origin rpy="0 3.14 0" xyz="0.02 -0.01 -0.02"/>
    <dynamics damping="0.0"/>
  </joint>
  <joint name="joint12" type="revolute">
    <parent link="servo_r5"/>
    <child link="r_bracket6"/>
    <origin rpy="0 3.14 1.57" xyz="0.02 0.01 0.04"/>
    <axis xyz="0 1 0"/>
    <limit effort="100" lower="-1.57" upper="1.57" velocity="0.5"/>
    <dynamics damping="0.0"/>
  </joint>
  <joint name="joint13" type="revolute">
    <parent link="r_bracket6"/>
    <child link="servo_r6"/>
    <origin rpy="0 3.14 0" xyz="0.02 0 -0.02"/>
    <axis xyz="0 0 1"/>
    <limit effort="100" lower="-1.57" upper="1.57" velocity="0.5"/>
    <dynamics damping="0.0"/>
  </joint>
  <joint name="servo_r6_link" type="fixed">
    <parent link="servo_r6"/>
    <child link="r_bracket7"/>
    <origin rpy="0 3.14 1.57" xyz="0.02 0.01 0.04"/>
    <axis xyz="0 1 0"/>
    <limit effort="100" lower="-1.57" upper="1.57" velocity="0.5"/>
    <dynamics damping="0.0"/>
  </joint>
  <joint name="servo_r7_link" type="fixed">
    <parent link="servo_r6"/>
    <child link="servo_r7"/>
    <origin rpy="0 0 0" xyz="0 0 0.06"/>
    <axis xyz="0 1 0"/>
    <limit effort="100" lower="-1.57" upper="1.57" velocity="0.5"/>
    <dynamics damping="0.0"/>
  </joint>
  <joint name="joint14" type="revolute">
    <parent link="servo_r7"/>
    <child link="r_bracket8"/>
    <origin rpy="0 3.14 1.57" xyz="0.02 0 0.04"/>
    <axis xyz="0 1 0"/>
    <limit effort="100" lower="-1.57" upper="1.57" velocity="0.5"/>
    <dynamics damping="0.0"/>
  </joint>
  <link name="right_gripper_base">
    <visual>
      <origin rpy="0 0 0" xyz="0 -0.03 -0.015"/>
      <geometry>
        <box size="0.032 0.06 0.01"/>
      </geometry>
      <material name="gold">
        <color rgba="0.5 0.3 0 1.0"/>
      </material>
    </visual>
    <collision>
      <origin rpy="0 0 0" xyz="0 -0.03 -0.015"/>
      <geometry>
        <box size="0.032 0.06 0.01"/>
      </geometry>
      <inertial>
        <mass value="0.01"/>
        <inertia ixx="0.0001" ixy="0.0" ixz="0.0" iyy="0.0001" iyz="0.0" izz="0.0001"/>
      </inertial>
    </collision>
  </link>
  <gazebo reference="right_gripper_base">
    <material>Gazebo/FlatBlack</material>
    <selfCollide>false</selfCollide>
    <turnGravityOff>false</turnGravityOff>
  </gazebo>
  <link name="right_right_claw">
    <visual>
      <geometry>
        <mesh filename="package://r2_description/mesh/claw_3_rr.stl" scale="0.001 0.001 0.001"/>
      </geometry>
      <material name="White">
        <color rgba="1.0 1.0 1.0 1.0"/>
      </material>
      <origin rpy="0 0 0" xyz="0 0 0"/>
    </visual>
    <collision>
      <origin rpy="0 0 0" xyz="0 0 0"/>
      <geometry>
        <mesh filename="package://r2_description/mesh/claw_3_rr.stl" scale="0.001 0.001 0.001"/>
      </geometry>
    </collision>
  </link>
  <link name="right_left_claw">
    <visual>
      <geometry>
        <mesh filename="package://r2_description/mesh/claw_3_l.stl" scale="0.001 0.001 0.001"/>
      </geometry>
      <material name="White">
        <color rgba="1.0 1.0 1.0 1.0"/>
      </material>
      <origin rpy="0 0 0" xyz="0 0 0"/>
    </visual>
    <collision>
      <origin rpy="0 0 0" xyz="0 0 0"/>
      <geometry>
        <mesh filename="package://r2_description/mesh/claw_3_l.stl" scale="0.001 0.001 0.001"/>
      </geometry>
    </collision>
  </link>
  <joint name="right_gripper_base_joint" type="fixed">
    <parent link="r_bracket8"/>
    <child link="right_gripper_base"/>
    <origin rpy="-1.57 0 0" xyz="0 0 -0.07"/>
    <axis xyz="0 0 1"/>
    <limit effort="10" lower="-0.64" upper="0" velocity="1"/>
    <dynamics damping="0.0"/>
  </joint>
  <joint name="joint15" type="revolute">
    <parent link="right_gripper_base"/>
    <child link="right_right_claw"/>
    <origin rpy="0 0 0" xyz="0 0 0"/>
    <axis xyz="0 0 1"/>
    <limit effort="10" lower="-1.3" upper="0.0" velocity="1"/>
    <dynamics damping="0.0"/>
  </joint>
  <joint name="right_gripper_finger_joint2" type="fixed">
    <parent link="right_gripper_base"/>
    <child link="right_left_claw"/>
    <origin rpy="0 0 0" xyz="0 0 0"/>
    <axis xyz="0 0 1"/>
    <limit effort="10" lower="-0.64" upper="0.0" velocity="1"/>
    <!--<mimic joint="${side}_gripper_finger_joint" multiplier="-1" offset="0"/> -->
    <dynamics damping="0.0"/>
  </joint>
  <!-- Fake gripper link and joint for grasp planning -->
  <joint name="right_gripper_joint" type="fixed">
    <origin rpy="0 0 1.57" xyz="0 0.03 0"/>
    <parent link="right_right_claw"/>
    <child link="right_gripper_link"/>
  </joint>
  <link name="right_gripper_link">
    <visual>
      <origin rpy="0 0 0" xyz="-0.05 0 0"/>
      <geometry>
        <box size="0.001 0.001 0.001"/>
      </geometry>
    </visual>
    <collision>
      <origin rpy="0 0 0" xyz="-0.05 0 0"/>
      <geometry>
        <box size="0.001 0.001 0.001"/>
      </geometry>
    </collision>
    <!--inertial>
         <mass value="0.0012" />
         <origin xyz="0 0 0"/>
         <inertia ixx="2e-8" ixy="0.0" ixz="0.0"
          iyy="2e-8" iyz="0.0"
          izz="2e-8" />
      </inertial -->
  </link>
  <!-- ##############################   joints ##################333333-->
  <joint name="base_footprint" type="fixed">
    <parent link="base_footprint"/>
    <child link="base_link"/>
    <origin rpy="0 0 0" xyz="0.06 0 0.06"/>
  </joint>
  <joint name="torso_link" type="fixed">
    <parent link="base_link"/>
    <child link="torso_link"/>
    <origin rpy="0 0 0" xyz="0.0 0 0.012"/>
  </joint>
  <joint name="imu_link" type="fixed">
    <parent link="base_link"/>
    <child link="imu_base"/>
    <origin rpy="0 0 0" xyz="0.0 0 0.72"/>
  </joint>
  <joint name="laser_frame" type="fixed">
    <parent link="base_link"/>
    <child link="scanner_link"/>
    <origin rpy="0 0 3.14" xyz="0.1 0 0.63"/>
  </joint>
  <joint name="pan_link" type="fixed">
    <parent link="torso_link"/>
    <child link="pan_link"/>
    <origin rpy="0 0 0" xyz="0.02 0 0.68"/>
  </joint>
  <!-- head_pan_joint-->
  <joint name="joint16" type="revolute">
    <parent link="pan_link"/>
    <child link="head_pan_link"/>
    <origin rpy="0 0 3.14159" xyz="-0.04 0 0.02"/>
    <origin rpy="0 0 0" xyz="0 0 0.0"/>
    <axis xyz="0 0 1"/>
    <limit effort="100" lower="-2" upper="2" velocity="0.5"/>
    <dynamics damping="0.0"/>
  </joint>
  <!-- head_tilt_servo-->
  <joint name="head_tilt_link" type="fixed">
    <parent link="head_pan_link"/>
    <child link="head_tilt_link"/>
    <origin rpy="0 0 0" xyz="-0.06 0 0.04"/>
  </joint>
  <!-- head_tilt_joint-->
  <joint name="joint17" type="revolute">
    <parent link="head_tilt_link"/>
    <child link="head_tilt_r_bracket_f2"/>
    <origin rpy="0 0 3.14" xyz="0 0 0.0"/>
    <axis xyz="0 1 0"/>
    <limit effort="100" lower="2" upper="-2" velocity="0.5"/>
    <dynamics damping="0.0"/>
  </joint>
  <!-- neck-->
  <joint name="neck_link" type="fixed">
    <parent link="head_tilt_r_bracket_f2"/>
    <child link="neck"/>
    <origin rpy="0 0 0" xyz="0 0 0.05"/>
  </joint>
  <!-- head-->
  <joint name="head_link" type="fixed">
    <parent link="neck"/>
    <child link="head"/>
    <origin rpy="0 0 0" xyz="0 0 0.05"/>
  </joint>
  <!-- camera-->
  <joint name="camera_link" type="fixed">
    <parent link="head"/>
    <child link="camera_link"/>
    <origin rpy="0 0 3.14159" xyz="0.065 0.055 0.005"/>
  </joint>
  <link name="d435_link">
    <visual>
      <origin rpy="1.570795 0 1.570795" xyz="0.0149 -0.0175 0"/>
      <geometry>
        <!--<box size="${d435_cam_width} ${d435_cam_height} ${d435_cam_depth}"/> -->
        <mesh filename="package://robbie/mesh/d435.dae"/>
      </geometry>
    </visual>
    <collision>
      <origin rpy="0 0 0" xyz="0 -0.0175 0"/>
      <geometry>
        <box size="0.02505 0.09 0.025"/>
      </geometry>
    </collision>
    <inertial>
      <!-- The following are not reliable values, and should not be used for modeling -->
      <mass value="0.564"/>
      <origin xyz="0 0 0"/>
      <inertia ixx="0.003881243" ixy="0.0" ixz="0.0" iyy="0.000498940" iyz="0.0" izz="0.003879257"/>
    </inertial>
  </link>
  <!--############################# left arm ################-->
  <joint name="joint0" type="revolute">
    <parent link="torso_link"/>
    <child link="left_rotate"/>
    <origin rpy="0 0 0" xyz="0.01 0.13 0.65"/>
    <axis xyz="0 0 1"/>
    <limit effort="100" lower="-1.34" upper="1.15" velocity="0.5"/>
    <dynamics damping="0.0"/>
  </joint>
  <joint name="joint1" type="revolute">
    <parent link="left_rotate"/>
    <child link="left_lift_link"/>
    <origin rpy="0 0 0" xyz="0 0.03 0"/>
    <axis xyz="0 1 0"/>
    <limit effort="100" lower="-1.57" upper="1.57" velocity="0.5"/>
    <dynamics damping="0.0"/>
  </joint>
  <joint name="joint2" type="revolute">
    <parent link="left_lift_link"/>
    <child link="elbow_joint_l"/>
    <origin rpy="0 0 0" xyz="0.15 0.03 -0"/>
    <axis xyz="1 0 0"/>
    <limit effort="100" lower="-1.57" upper="1.57" velocity="0.5"/>
    <dynamics damping="0.0"/>
  </joint>
  <joint name="servo_l4_link" type="fixed">
    <parent link="elbow_joint_l"/>
    <child link="servo_l4"/>
    <origin rpy="1.57 0 1.57" xyz="0.02 -0.02 -0.01"/>
    <dynamics damping="0.0"/>
  </joint>
  <joint name="joint3" type="revolute">
    <parent link="servo_l4"/>
    <child link="l_bracket5"/>
    <origin rpy="0 3.14 1.57" xyz="0.02 0.01 0.04"/>
    <axis xyz="0 1 0"/>
    <limit effort="100" lower="-1.57" upper="1.57" velocity="0.5"/>
    <dynamics damping="0.0"/>
  </joint>
  <joint name="servo_l5_link" type="fixed">
    <parent link="l_bracket5"/>
    <child link="servo_l5"/>
    <origin rpy="0 3.14 0" xyz="0.02 -0.01 -0.02"/>
    <dynamics damping="0.0"/>
  </joint>
  <joint name="joint4" type="revolute">
    <parent link="servo_l5"/>
    <child link="l_bracket6"/>
    <origin rpy="0 3.14 1.57" xyz="0.02 0.01 0.04"/>
    <axis xyz="0 1 0"/>
    <limit effort="100" lower="-1.57" upper="1.57" velocity="0.5"/>
    <dynamics damping="0.0"/>
  </joint>
  <joint name="joint5" type="revolute">
    <parent link="l_bracket6"/>
    <child link="servo_l6"/>
    <origin rpy="0 3.14 0" xyz="0.02 0 -0.02"/>
    <axis xyz="0 0 1"/>
    <limit effort="100" lower="-1.57" upper="1.57" velocity="0.5"/>
    <dynamics damping="0.0"/>
  </joint>
  <joint name="servo_l6_link" type="fixed">
    <parent link="servo_l6"/>
    <child link="l_bracket7"/>
    <origin rpy="0 3.14 1.57" xyz="0.02 0.01 0.04"/>
    <axis xyz="0 1 0"/>
    <limit effort="100" lower="-1.57" upper="1.57" velocity="0.5"/>
    <dynamics damping="0.0"/>
  </joint>
  <joint name="servo_l7_link" type="fixed">
    <parent link="servo_l6"/>
    <child link="servo_l7"/>
    <origin rpy="0 0 0" xyz="0 0 0.06"/>
    <axis xyz="0 1 0"/>
    <limit effort="100" lower="-1.57" upper="1.57" velocity="0.5"/>
    <dynamics damping="0.0"/>
  </joint>
  <joint name="joint6" type="revolute">
    <parent link="servo_l7"/>
    <child link="l_bracket8"/>
    <origin rpy="0 3.14 1.57" xyz="0.02 0 0.04"/>
    <axis xyz="0 1 0"/>
    <limit effort="100" lower="-1.57" upper="1.57" velocity="0.5"/>
    <dynamics damping="0.0"/>
  </joint>
  <link name="left_gripper_base">
    <visual>
      <origin rpy="0 0 0" xyz="0 -0.03 -0.015"/>
      <geometry>
        <box size="0.032 0.06 0.01"/>
      </geometry>
      <material name="gold">
        <color rgba="0.5 0.3 0 1.0"/>
      </material>
    </visual>
    <collision>
      <origin rpy="0 0 0" xyz="0 -0.03 -0.015"/>
      <geometry>
        <box size="0.032 0.06 0.01"/>
      </geometry>
      <inertial>
        <mass value="0.01"/>
        <inertia ixx="0.0001" ixy="0.0" ixz="0.0" iyy="0.0001" iyz="0.0" izz="0.0001"/>
      </inertial>
    </collision>
  </link>
  <gazebo reference="left_gripper_base">
    <material>Gazebo/FlatBlack</material>
    <selfCollide>false</selfCollide>
    <turnGravityOff>false</turnGravityOff>
  </gazebo>
  <link name="left_right_claw">
    <visual>
      <geometry>
        <mesh filename="package://r2_description/mesh/claw_3_rr.stl" scale="0.001 0.001 0.001"/>
      </geometry>
      <material name="White">
        <color rgba="1.0 1.0 1.0 1.0"/>
      </material>
      <origin rpy="0 0 0" xyz="0 0 0"/>
    </visual>
    <collision>
      <origin rpy="0 0 0" xyz="0 0 0"/>
      <geometry>
        <mesh filename="package://r2_description/mesh/claw_3_rr.stl" scale="0.001 0.001 0.001"/>
      </geometry>
    </collision>
  </link>
  <link name="left_left_claw">
    <visual>
      <geometry>
        <mesh filename="package://r2_description/mesh/claw_3_l.stl" scale="0.001 0.001 0.001"/>
      </geometry>
      <material name="White">
        <color rgba="1.0 1.0 1.0 1.0"/>
      </material>
      <origin rpy="0 0 0" xyz="0 0 0"/>
    </visual>
    <collision>
      <origin rpy="0 0 0" xyz="0 0 0"/>
      <geometry>
        <mesh filename="package://r2_description/mesh/claw_3_l.stl" scale="0.001 0.001 0.001"/>
      </geometry>
    </collision>
  </link>
  <joint name="left_gripper_base_joint" type="fixed">
    <parent link="l_bracket8"/>
    <child link="left_gripper_base"/>
    <origin rpy="-1.57 0 0" xyz="0 0 -0.07"/>
    <axis xyz="0 0 1"/>
    <limit effort="10" lower="-0.64" upper="0" velocity="1"/>
    <dynamics damping="0.0"/>
  </joint>
  <joint name="joint7" type="revolute">
    <parent link="left_gripper_base"/>
    <child link="left_right_claw"/>
    <origin rpy="0 0 0" xyz="0 0 0"/>
    <axis xyz="0 0 1"/>
    <limit effort="10" lower="-1.3" upper="0.0" velocity="1"/>
    <dynamics damping="0.0"/>
  </joint>
  <joint name="left_gripper_finger_joint2" type="fixed">
    <parent link="left_gripper_base"/>
    <child link="left_left_claw"/>
    <origin rpy="0 0 0" xyz="0 0 0"/>
    <axis xyz="0 0 1"/>
    <limit effort="10" lower="-0.64" upper="0.0" velocity="1"/>
    <!--<mimic joint="${side}_gripper_finger_joint" multiplier="-1" offset="0"/> -->
    <dynamics damping="0.0"/>
  </joint>
  <!-- Fake gripper link and joint for grasp planning -->
  <joint name="left_gripper_joint" type="fixed">
    <origin rpy="0 0 1.57" xyz="0 0.03 0"/>
    <parent link="left_right_claw"/>
    <child link="left_gripper_link"/>
  </joint>
  <link name="left_gripper_link">
    <visual>
      <origin rpy="0 0 0" xyz="-0.05 0 0"/>
      <geometry>
        <box size="0.001 0.001 0.001"/>
      </geometry>
    </visual>
    <collision>
      <origin rpy="0 0 0" xyz="-0.05 0 0"/>
      <geometry>
        <box size="0.001 0.001 0.001"/>
      </geometry>
    </collision>
    <!--inertial>
         <mass value="0.0012" />
         <origin xyz="0 0 0"/>
         <inertia ixx="2e-8" ixy="0.0" ixz="0.0"
          iyy="2e-8" iyz="0.0"
          izz="2e-8" />
      </inertial -->
  </link>
  <joint name="kinect_joint" type="fixed">
    <parent link="base_link"/>
    <child link="kinect_link"/>
    <origin rpy="0 0 0" xyz="0.09 0 0.22"/>
  </joint>
  <joint name="kinect_depth_joint" type="fixed">
    <origin rpy="0 0 0" xyz="0 0.0125 0.015"/>
    <parent link="kinect_link"/>
    <child link="kinect_depth_frame"/>
  </joint>
  <link name="kinect_depth_frame">
    <inertial>
      <mass value="0.000001"/>
      <origin xyz="0 0 0"/>
      <inertia ixx="0.0001" ixy="0.0" ixz="0.0" iyy="0.0001" iyz="0.0" izz="0.0001"/>
    </inertial>
  </link>
  <joint name="kinect_depth_optical_joint" type="fixed">
    <origin rpy="-1.57075 0 -1.57075" xyz="0 0 0"/>
    <parent link="kinect_depth_frame"/>
    <child link="kinect_depth_optical_frame"/>
  </joint>
  <link name="kinect_depth_optical_frame">
    <inertial>
      <mass value="0.000001"/>
      <origin xyz="0 0 0"/>
      <inertia ixx="0.0001" ixy="0.0" ixz="0.0" iyy="0.0001" iyz="0.0" izz="0.0001"/>
    </inertial>
  </link>
  <joint name="kinect_rgb_joint" type="fixed">
    <origin rpy="0 0 0" xyz="0 -0.0125 0.01"/>
    <parent link="kinect_link"/>
    <child link="kinect_rgb_frame"/>
  </joint>
  <link name="kinect_rgb_frame">
    <inertial>
      <mass value="0.000001"/>
      <origin xyz="0 0 0"/>
      <inertia ixx="0.0001" ixy="0.0" ixz="0.0" iyy="0.0001" iyz="0.0" izz="0.0001"/>
    </inertial>
  </link>
  <joint name="kinect_rgb_optical_joint" type="fixed">
    <origin rpy="-1.57075 0 -1.57075" xyz="0 0 0"/>
    <parent link="kinect_rgb_frame"/>
    <child link="kinect_rgb_optical_frame"/>
  </joint>
  <link name="kinect_rgb_optical_frame">
    <inertial>
      <mass value="0.000001"/>
      <origin xyz="0 0 0"/>
      <inertia ixx="0.0001" ixy="0.0" ixz="0.0" iyy="0.0001" iyz="0.0" izz="0.0001"/>
    </inertial>
  </link>
  <joint name="d435_joint" type="fixed">
    <parent link="head"/>
    <child link="d435_link"/>
    <origin rpy="0 0 0" xyz="0.02 0.018 -0.06"/>
  </joint>
</robot>
