<?xml version="1.0"?>

<robot name="gripper" xmlns:xacro="http://www.ros.org/wiki/xacro">

    <xacro:property name="PI" value="3.1415" />  
    <xacro:property name="M_PI" value="3.14159"/>
    <xacro:property name="M_SCALE" value="0.001"/>
    <xacro:property name="C_SCALE" value="0.0034"/>
    <xacro:property name="MESH_EXT" value="stl"/>
    <xacro:property name="color" value="grey1"/>
    <xacro:include filename="$(find r2_description)/urdf/hardware.xacro" />

   
    <xacro:macro name="gripper" params="side reflect parent *origin num"> 


<xacro:my_box name="${side}_gripper_base" lwh="0.032 0.06 0.01" xyz="0 -0.03 -0.015" rpy="0 0 0" mass="0.1" material="Gazebo/FlatBlack">
	        <xacro:gold />
        </xacro:my_box>

   <link name="${side}_right_claw" >
   <visual>
      <geometry>
        <mesh filename="package://r2_description/mesh/claw_3_rr.stl" scale="${M_SCALE} ${M_SCALE} ${M_SCALE}"/>
      </geometry>
         <xacro:White/>
      <origin rpy="0 0 0" xyz="0 0 0"/>
    </visual>
   <collision>
        <origin xyz="0 0 0" rpy="0 0 0" />
        <geometry>
          <mesh filename="package://r2_description/mesh/claw_3_rr.stl" scale="${M_SCALE} ${M_SCALE} ${M_SCALE}"/>
          </geometry>
      </collision>
  </link>

   <link name="${side}_left_claw" >
   <visual>
      <geometry>
        <mesh filename="package://r2_description/mesh/claw_3_l.stl" scale="${M_SCALE} ${M_SCALE} ${M_SCALE}"/>
      </geometry>
         <xacro:White/>
      <origin rpy="0 0 0" xyz="0 0 0"/>
    </visual>
   <collision>
        <origin xyz="0 0 0" rpy="0 0 0" />
        <geometry>
          <mesh filename="package://r2_description/mesh/claw_3_l.stl" scale="${M_SCALE} ${M_SCALE} ${M_SCALE}"/>
          </geometry>
      </collision>
  </link>

  <joint name="${side}_gripper_base_joint" type="fixed">
    	<parent link="${parent}" />
    	<child link="${side}_gripper_base" />
        <origin xyz="0 0 -0.07" rpy="-1.57 0 0" />
    	<axis xyz="0 0 1" />
    	<limit lower="-0.64" upper="0" effort="10" velocity="1" />
      	<dynamics damping="0.0"/>
	</joint>

  <joint name="${num}" type="revolute">
    	<parent link="${side}_gripper_base" />
    	<child link="${side}_right_claw" />
        <origin xyz="0 0 0" rpy="0 0 0" />
    	<axis xyz="0 0 1" />
    	<limit lower="-1.3" upper="0.0" effort="10" velocity="1" />
      	<dynamics damping="0.0"/>
	</joint>

  <joint name="${side}_gripper_finger_joint2" type="fixed">
    	<parent link="${side}_gripper_base" />
    	<child link="${side}_left_claw" />
        <origin xyz="0 0 0" rpy="0 0 0" />
    	<axis xyz="0 0 1" />
    	<limit lower="-0.64" upper="0.0" effort="10" velocity="1" />
        <!--<mimic joint="${side}_gripper_finger_joint" multiplier="-1" offset="0"/> -->
      	<dynamics damping="0.0"/>
	</joint>

  <!-- Fake gripper link and joint for grasp planning -->
    <joint name="${side}_gripper_joint" type="fixed">
      <origin xyz="0 0.03 0" rpy="0 0 1.57"/>
      <parent link="${side}_right_claw"/>
      <child link="${side}_gripper_link"/>
    </joint>
    <link name="${side}_gripper_link">
      <visual>
        <origin xyz="-0.05 0 0" rpy="0 0 0"/>
        <geometry>
           <box size="0.001 0.001 0.001"/>
        </geometry>
      </visual>
      <collision>
        <origin xyz="-0.05 0 0" rpy="0 0 0"/>
        <geometry>
           <box size="0.001 0.001 0.001"/>
        </geometry>
      </collision>
      <!--inertial>
         <mass value="0.0012" />
         <origin xyz="0 0 0"/>
         <inertia ixx="2e-8" ixy="0.0" ixz="0.0"
          iyy="2e-8" iyz="0.0"
          izz="2e-8" />
      </inertial -->
    </link>
</xacro:macro>
</robot>
